Workbook

Sheet Lån Översikt
B3: Input parametrar | F3: Månad | G3: Huslån (kr) | H3: Listränta (kr/mån) | I3: Drift+fastighet (kr/mån) | J3: Ammortering (kr/mån) | K3: Renovering (kr/mån) | L3: Totalt hus (kr/mån) | M3: Totalt ut (kr/mån) | N3: Totalt kvar (kr/mån)
B4: Huspris | C4: 5000000 | D4: JA | F4: 1 | G4: =C5 -> 3750000 | H4: =INT(IF(AND($D$7="JA", $D$11="JA", $D$8="JA"), (C5*(($C$7/100*$C$11/100)-$C$8/100))/12, IF(AND($D$7="JA", $D$11="JA", $D$8="NEJ"), (C5*(($C$7/100*$C$11/100))/12), 0))) -> 9584 | I4: =INT(SUM(C9:C10)/12) -> 4712 | J4: =INT((C5*C15/100)/12) -> 6250 | K4: =INT((C4*C14/100)/12) -> 4166 | L4: =INT(SUM(H4:K4)) -> 24712 | M4: =(L4 + $D$50) -> 46661 | N4: =($D$24 - M4) -> 3139
B5: Huslån | C5: =(C4*C12/100) -> 3750000 | D5: JA | F5: =Data!F27 -> 24 | G5: =Data!G27 -> 3606250 | H5: =Data!H27 -> 9216 | I5: =Data!I27 -> 4712 | J5: =Data!J27 -> 6250 | K5: =Data!K27 -> 4166 | L5: =Data!L27 -> 24344 | M5: =Data!M27 -> 46293 | N5: =Data!N27 -> 3507
B6: Kontantinsats | C6: =(C4*(1-C12/100)) -> 1250000 | D6: JA | F6: =Data!F51 -> 48 | G6: =Data!G51 -> 3456250 | H6: =Data!H51 -> 8833 | I6: =Data!I51 -> 4712 | J6: =Data!J51 -> 6250 | K6: =Data!K51 -> 4166 | L6: =Data!L51 -> 23961 | M6: =Data!M51 -> 45910 | N6: =Data!N51 -> 3890
B7: Listränta (%) | C7: 3.067 | D7: JA | F7: =Data!F75 -> 72 | G7: =Data!G75 -> 3306250 | H7: =Data!H75 -> 8450 | I7: =Data!I75 -> 4712 | J7: =Data!J75 -> 6250 | K7: =Data!K75 -> 4166 | L7: =Data!L75 -> 23578 | M7: =Data!M75 -> 45527 | N7: =Data!N75 -> 4273
B8: Inflation | C8: 1 | D8: NEJ | F8: =Data!F99 -> 96 | G8: =Data!G99 -> 3156250 | H8: =Data!H99 -> 8066 | I8: =Data!I99 -> 4712 | J8: =Data!J99 -> 6250 | K8: =Data!K99 -> 4166 | L8: =Data!L99 -> 23194 | M8: =Data!M99 -> 45143 | N8: =Data!N99 -> 4657
B9: Driftkostnad | C9: 47025 | D9: JA | F9: =Data!F123 -> 120 | G9: =Data!G123 -> 3006250 | H9: =Data!H123 -> 7683 | I9: =Data!I123 -> 4712 | J9: =Data!J123 -> 6250 | K9: =Data!K123 -> 4166 | L9: =Data!L123 -> 22811 | M9: =Data!M123 -> 44760 | N9: =Data!N123 -> 5040
B10: Fastighetsavgift | C10: 9525 | D10: JA | F10: =Data!F147 -> 144 | G10: =Data!G147 -> 2856250 | H10: =Data!H147 -> 7300 | I10: =Data!I147 -> 4712 | J10: =Data!J147 -> 6250 | K10: =Data!K147 -> 4166 | L10: =Data!L147 -> 22428 | M10: =Data!M147 -> 44377 | N10: =Data!N147 -> 5423
B11: Skattereduktion | C11: 100 | D11: JA | F11: =Data!F171 -> 168 | G11: =Data!G171 -> 2706250 | H11: =Data!H171 -> 6916 | I11: =Data!I171 -> 4712 | J11: =Data!J171 -> 6250 | K11: =Data!K171 -> 4166 | L11: =Data!L171 -> 22044 | M11: =Data!M171 -> 43993 | N11: =Data!N171 -> 5807
B12: Bolån | C12: 75 | D12: JA | F12: =Data!F195 -> 192 | G12: =Data!G195 -> 2587500 | H12: =Data!H195 -> 6613 | I12: =Data!I195 -> 4712 | J12: =Data!J195 -> 3125 | K12: =Data!K195 -> 4166 | L12: =Data!L195 -> 18616 | M12: =Data!M195 -> 40565 | N12: =Data!N195 -> 9235
B13: Lagfart | C13: =(0.015*C4) -> 75000 | D13: JA | F13: =Data!F219 -> 216 | G13: =Data!G219 -> 2512500 | H13: =Data!H219 -> 6421 | I13: =Data!I219 -> 4712 | J13: =Data!J219 -> 3125 | K13: =Data!K219 -> 4166 | L13: =Data!L219 -> 18424 | M13: =Data!M219 -> 40373 | N13: =Data!N219 -> 9427
B14: Renovering (%) | C14: 1 | D14: JA | F14: =Data!F243 -> 240 | G14: =Data!G243 -> 2437500 | H14: =Data!H243 -> 6229 | I14: =Data!I243 -> 4712 | J14: =Data!J243 -> 3125 | K14: =Data!K243 -> 4166 | L14: =Data!L243 -> 18232 | M14: =Data!M243 -> 40181 | N14: =Data!N243 -> 9619
B15: Ammortering (%) | C15: =IF(C16>C5,2,3) -> 2 | D15: JA | F15: =Data!F267 -> 264 | G15: =Data!G267 -> 2362500 | H15: =Data!H267 -> 6038 | I15: =Data!I267 -> 4712 | J15: =Data!J267 -> 3125 | K15: =Data!K267 -> 4166 | L15: =Data!L267 -> 18041 | M15: =Data!M267 -> 39990 | N15: =Data!N267 -> 9810
B16: Reduktionsgräns | C16: =(48000*12 + 32250*12)*4.5 -> 4333500 | D16: =IF(C5<C16,"JA","NEJ") -> JA
B17: Pantbrev | C17: =0.02*(C5 - 4208000) -> -9160 | D17: NEJ
B18: Ammort. Reduktion | C18: =MIN(G4:G1005) <= G4 * 0.7 -> TRUE | D18: JA
B19: Lantmäteriavgift | C19: 825 | D19: JA
B21: Pengar in | C21: Inkomst (efter skatt) | D21: Föräldrarledig
B22: Markus | C22: =IF(D22 = "NEJ", 36800, 15586) -> 36800 | D22: NEJ
B23: Maja | C23: =IF(D23 = "NEJ", 29500, 13000) -> 13000 | D23: JA
B24: Totalt: | D24: =SUM(C22:C23) -> 49800
B26: Utgifter exkl. hyra | C26: Belopp
B27: Mat/hushåll. | C27: 6000 | D27: JA
B28: Internet | C28: 399 | D28: JA
B29: Bilförsäkring | C29: 882 | D29: JA
B30: Milas försäkring | C30: 231 | D30: JA
B31: Villaförsäkring | C31: 622 | D31: JA
B32: Guccis försäkring | C32: 127 | D32: JA
B33: Kortavgift | C33: 70 | D33: JA
B34: CSN | C34: 1100 | D34: JA
B35: Spotify | C35: 100 | D35: JA
B36: Youtube | C36: 119 | D36: JA
B37: Gym | C37: 279 | D37: JA
B38: Sparande Mila | C38: 1000 | D38: JA
... B40: Billån Maja | C40: 2775 | D40: JA
B41: Abonnemang | C41: 229 | D41: JA | F41: Totalt engångs köp: | H41: =SUM(C6,C13,C19) -> 1325825
B42: Mobil | C42: 250 | D42: JA | F42: Totalt förlorat under FL: | H42: =IF(D22 = "JA", -1*SUM(Data!N5:N10), 0) -> 0
B43: Glasögon | C43: 331 | D43: JA | F43: Total buffert efter köp: | H43: =(#REF!-H41-H42) -> #REF!
B44: Bankkort | C44: 80 | D44: JA
B45: Föräkring Maja | C45: 229 | D45: JA
...

Sheet Data
F3: Månad | G3: Huslån | H3: Listränta (kr/mån) | I3: Drift+fastighet (kr/mån) | J3: Ammortering (kr/mån) | K3: Renovering (kr/mån) | L3: Totalt hus (kr/mån) | M3: Totalt ut (kr/mån) | N3: Totalt kvar (kr/mån) | O3: Check 1 | P3: Check 2 | Q3: Check 3
F4: 1 | G4: ='Lån Översikt'!C5 -> 3750000 | H4: =INT(IF(AND('Lån Översikt'!$D$7="JA", 'Lån Översikt'!$D$11="JA", 'Lån Översikt'!$D$8="JA"), ('Lån Översikt'!C5*(('Lån Översikt'!$C$7/100*'Lån Översikt'!$C$11/100)-'Lån Översikt'!$C$8/100))/12, IF(AND('Lån Översikt'!$D$7="JA", 'Lån Översikt'!$D$11="JA", 'Lån Översikt'!$D$8="NEJ"), ('Lån Översikt'!C5*(('Lån Översikt'!$C$7/100*'Lån Översikt'!$C$11/100))/12), 0))) -> 9584 | I4: =INT(SUM('Lån Översikt'!C9:'Lån Översikt'!C10)/12) -> 4712 | J4: =INT((('Lån Översikt'!C5*'Lån Översikt'!C15/100)/12)) -> 6250 | K4: =INT(('Lån Översikt'!C4*'Lån Översikt'!C14/100)/12) -> 4166 | L4: =INT(SUM('Lån Översikt'!H4:'Lån Översikt'!K4)) -> 24712 | M4: =(L4 + 'Lån Översikt'!$D$50) -> 46661 | N4: =('Lån Översikt'!$D$24 - M4) -> 3139
F5: 2 | G5: =(G4-J4) -> 3743750 | H5: =INT(IF(AND('Lån Översikt'!$D$7="JA", 'Lån Översikt'!$D$11="JA", 'Lån Översikt'!$D$8="JA"), (G5*(('Lån Översikt'!$C$7/100*'Lån Översikt'!$C$11/100)-'Lån Översikt'!$C$8/100))/12, IF(AND('Lån Översikt'!$D$7="JA", 'Lån Översikt'!$D$11="JA", 'Lån Översikt'!$D$8="NEJ"), (G5*(('Lån Översikt'!$C$7/100*'Lån Översikt'!$C$11/100))/12), 0))) -> 9568 | I5: =I4 -> 4712 | J5: =IF(AND(P5, O5), 0, IF(O5, INT((('Lån Översikt'!$C$5 * 1 / 100) / 12)), INT((('Lån Översikt'!$C$5 * 'Lån Översikt'!$C$15 / 100) / 12)))) -> 6250 | K5: =K4 -> 4166 | L5: =INT(SUM(H5:K5)) -> 24696 | M5: =(L5 + 'Lån Översikt'!$D$50) -> 46645 | N5: =IF('Lån Översikt'!$D$22 = "JA", IF(Q5 = TRUE, 'Lån Översikt'!$D$24 - M5, 'Lån Översikt'!$D$24 - M5 + 18300), 'Lån Översikt'!$D$24 - M5) -> 3155 | O5: =IF(G5 < 0.7*$G$4,TRUE, FALSE) -> FALSE | P5: =IF(G5 < 0.5*$G$4,TRUE, FALSE) -> FALSE | Q5: =IF(F4 < 7,TRUE, FALSE) -> TRUE
F6: 3 | G6: =(G5-J5) -> 3737500 | H6: =INT(IF(AND('Lån Översikt'!$D$7="JA", 'Lån Översikt'!$D$11="JA", 'Lån Översikt'!$D$8="JA"), (G6*(('Lån Översikt'!$C$7/100*'Lån Översikt'!$C$11/100)-'Lån Översikt'!$C$8/100))/12, IF(AND('Lån Översikt'!$D$7="JA", 'Lån Översikt'!$D$11="JA", 'Lån Översikt'!$D$8="NEJ"), (G6*(('Lån Översikt'!$C$7/100*'Lån Översikt'!$C$11/100))/12), 0))) -> 9552 | I6: =I5 -> 4712 | J6: =IF(AND(P6, O6), 0, IF(O6, INT((('Lån Översikt'!$C$5 * 1 / 100) / 12)), INT((('Lån Översikt'!$C$5 * 'Lån Översikt'!$C$15 / 100) / 12)))) -> 6250 | K6: =K5 -> 4166 | L6: =INT(SUM(H6:K6)) -> 24680 | M6: =(L6 + 'Lån Översikt'!$D$50) -> 46629 | N6: =IF('Lån Översikt'!$D$22 = "JA", IF(Q6 = TRUE, 'Lån Översikt'!$D$24 - M6, 'Lån Översikt'!$D$24 - M6 + 18300), 'Lån Översikt'!$D$24 - M6) -> 3171 | O6: =IF(G6 < 0.7*$G$4,TRUE, FALSE) -> FALSE | P6: =IF(G6 < 0.5*$G$4,TRUE, FALSE) -> FALSE | Q6: =IF(F5 < 7,TRUE, FALSE) -> TRUE
F7: 4 | G7: =(G6-J6) -> 3731250 | H7: =INT(IF(AND('Lån Översikt'!$D$7="JA", 'Lån Översikt'!$D$11="JA", 'Lån Översikt'!$D$8="JA"), (G7*(('Lån Översikt'!$C$7/100*'Lån Översikt'!$C$11/100)-'Lån Översikt'!$C$8/100))/12, IF(AND('Lån Översikt'!$D$7="JA", 'Lån Översikt'!$D$11="JA", 'Lån Översikt'!$D$8="NEJ"), (G7*(('Lån Översikt'!$C$7/100*'Lån Översikt'!$C$11/100))/12), 0))) -> 9536 | I7: =I6 -> 4712 | J7: =IF(AND(P7, O7), 0, IF(O7, INT((('Lån Översikt'!$C$5 * 1 / 100) / 12)), INT((('Lån Översikt'!$C$5 * 'Lån Översikt'!$C$15 / 100) / 12)))) -> 6250 | K7: =K6 -> 4166 | L7: =INT(SUM(H7:K7)) -> 24664 | M7: =(L7 + 'Lån Översikt'!$D$50) -> 46613 | N7: =IF('Lån Översikt'!$D$22 = "JA", IF(Q7 = TRUE, 'Lån Översikt'!$D$24 - M7, 'Lån Översikt'!$D$24 - M7 + 18300), 'Lån Översikt'!$D$24 - M7) -> 3187 | O7: =IF(G7 < 0.7*$G$4,TRUE, FALSE) -> FALSE | P7: =IF(G7 < 0.5*$G$4,TRUE, FALSE) -> FALSE | Q7: =IF(F6 < 7,TRUE, FALSE) -> TRUE
F8: 5 | G8: =(G7-J7) -> 3725000 | H8: =INT(IF(AND('Lån Översikt'!$D$7="JA", 'Lån Översikt'!$D$11="JA", 'Lån Översikt'!$D$8="JA"), (G8*(('Lån Översikt'!$C$7/100*'Lån Översikt'!$C$11/100)-'Lån Översikt'!$C$8/100))/12, IF(AND('Lån Översikt'!$D$7="JA", 'Lån Översikt'!$D$11="JA", 'Lån Översikt'!$D$8="NEJ"), (G8*(('Lån Översikt'!$C$7/100*'Lån Översikt'!$C$11/100))/12), 0))) -> 9520 | I8: =I7 -> 4712 | J8: =IF(AND(P8, O8), 0, IF(O8, INT((('Lån Översikt'!$C$5 * 1 / 100) / 12)), INT((('Lån Översikt'!$C$5 * 'Lån Översikt'!$C$15 / 100) / 12)))) -> 6250 | K8: =K7 -> 4166 | L8: =INT(SUM(H8:K8)) -> 24648 | M8: =(L8 + 'Lån Översikt'!$D$50) -> 46597 | N8: =IF('Lån Översikt'!$D$22 = "JA", IF(Q8 = TRUE, 'Lån Översikt'!$D$24 - M8, 'Lån Översikt'!$D$24 - M8 + 18300), 'Lån Översikt'!$D$24 - M8) -> 3203 | O8: =IF(G8 < 0.7*$G$4,TRUE, FALSE) -> FALSE | P8: =IF(G8 < 0.5*$G$4,TRUE, FALSE) -> FALSE | Q8: =IF(F7 < 7,TRUE, FALSE) -> TRUE
F9: 6 | G9: =(G8-J8) -> 3718750 | H9: =INT(IF(AND('Lån Översikt'!$D$7="JA", 'Lån Översikt'!$D$11="JA", 'Lån Översikt'!$D$8="JA"), (G9*(('Lån Översikt'!$C$7/100*'Lån Översikt'!$C$11/100)-'Lån Översikt'!$C$8/100))/12, IF(AND('Lån Översikt'!$D$7="JA", 'Lån Översikt'!$D$11="JA", 'Lån Översikt'!$D$8="NEJ"), (G9*(('Lån Översikt'!$C$7/100*'Lån Översikt'!$C$11/100))/12), 0))) -> 9504 | I9: =I8 -> 4712 | J9: =IF(AND(P9, O9), 0, IF(O9, INT((('Lån Översikt'!$C$5 * 1 / 100) / 12)), INT((('Lån Översikt'!$C$5 * 'Lån Översikt'!$C$15 / 100) / 12)))) -> 6250 | K9: =K8 -> 4166 | L9: =INT(SUM(H9:K9)) -> 24632 | M9: =(L9 + 'Lån Översikt'!$D$50) -> 46581 | N9: =IF('Lån Översikt'!$D$22 = "JA", IF(Q9 = TRUE, 'Lån Översikt'!$D$24 - M9, 'Lån Översikt'!$D$24 - M9 + 18300), 'Lån Översikt'!$D$24 - M9) -> 3219 | O9: =IF(G9 < 0.7*$G$4,TRUE, FALSE) -> FALSE | P9: =IF(G9 < 0.5*$G$4,TRUE, FALSE) -> FALSE | Q9: =IF(F8 < 7,TRUE, FALSE) -> TRUE
F10: 7 | G10: =(G9-J9) -> 3712500 | H10: =INT(IF(AND('Lån Översikt'!$D$7="JA", 'Lån Översikt'!$D$11="JA", 'Lån Översikt'!$D$8="JA"), (G10*(('Lån Översikt'!$C$7/100*'Lån Översikt'!$C$11/100)-'Lån Översikt'!$C$8/100))/12, IF(AND('Lån Översikt'!$D$7="JA", 'Lån Översikt'!$D$11="JA", 'Lån Översikt'!$D$8="NEJ"), (G10*(('Lån Översikt'!$C$7/100*'Lån Översikt'!$C$11/100))/12), 0))) -> 9488 | I10: =I9 -> 4712 | J10: =IF(AND(P10, O10), 0, IF(O10, INT((('Lån Översikt'!$C$5 * 1 / 100) / 12)), INT((('Lån Översikt'!$C$5 * 'Lån Översikt'!$C$15 / 100) / 12)))) -> 6250 | K10: =K9 -> 4166 | L10: =INT(SUM(H10:K10)) -> 24616 | M10: =(L10 + 'Lån Översikt'!$D$50) -> 46565 | N10: =IF('Lån Översikt'!$D$22 = "JA", IF(Q10 = TRUE, 'Lån Översikt'!$D$24 - M10, 'Lån Översikt'!$D$24 - M10 + 18300), 'Lån Översikt'!$D$24 - M10) -> 3235 | O10: =IF(G10 < 0.7*$G$4,TRUE, FALSE) -> FALSE | P10: =IF(G10 < 0.5*$G$4,TRUE, FALSE) -> FALSE | Q10: =IF(F9 < 7,TRUE, FALSE) -> TRUE
F11: 8 | G11: =(G10-J10) -> 3706250 | H11: =INT(IF(AND('Lån Översikt'!$D$7="JA", 'Lån Översikt'!$D$11="JA", 'Lån Översikt'!$D$8="JA"), (G11*(('Lån Översikt'!$C$7/100*'Lån Översikt'!$C$11/100)-'Lån Översikt'!$C$8/100))/12, IF(AND('Lån Översikt'!$D$7="JA", 'Lån Översikt'!$D$11="JA", 'Lån Översikt'!$D$8="NEJ"), (G11*(('Lån Översikt'!$C$7/100*'Lån Översikt'!$C$11/100))/12), 0))) -> 9472 | I11: =I10 -> 4712 | J11: =IF(AND(P11, O11), 0, IF(O11, INT((('Lån Översikt'!$C$5 * 1 / 100) / 12)), INT((('Lån Översikt'!$C$5 * 'Lån Översikt'!$C$15 / 100) / 12)))) -> 6250 | K11: =K10 -> 4166 | L11: =INT(SUM(H11:K11)) -> 24600 | M11: =(L11 + 'Lån Översikt'!$D$50) -> 46549 | N11: =IF('Lån Översikt'!$D$22 = "JA", IF(Q11 = TRUE, 'Lån Översikt'!$D$24 - M11, 'Lån Översikt'!$D$24 - M11 + 18300), 'Lån Översikt'!$D$24 - M11) -> 3251 | O11: =IF(G11 < 0.7*$G$4,TRUE, FALSE) -> FALSE | P11: =IF(G11 < 0.5*$G$4,TRUE, FALSE) -> FALSE | Q11: =IF(F10 < 7,TRUE, FALSE) -> FALSE
F12: 9 | G12: =(G11-J11) -> 3700000 | H12: =INT(IF(AND('Lån Översikt'!$D$7="JA", 'Lån Översikt'!$D$11="JA", 'Lån Översikt'!$D$8="JA"), (G12*(('Lån Översikt'!$C$7/100*'Lån Översikt'!$C$11/100)-'Lån Översikt'!$C$8/100))/12, IF(AND('Lån Översikt'!$D$7="JA", 'Lån Översikt'!$D$11="JA", 'Lån Översikt'!$D$8="NEJ"), (G12*(('Lån Översikt'!$C$7/100*'Lån Översikt'!$C$11/100))/12), 0))) -> 9456 | I12: =I11 -> 4712 | J12: =IF(AND(P12, O12), 0, IF(O12, INT((('Lån Översikt'!$C$5 * 1 / 100) / 12)), INT((('Lån Översikt'!$C$5 * 'Lån Översikt'!$C$15 / 100) / 12)))) -> 6250 | K12: =K11 -> 4166 | L12: =INT(SUM(H12:K12)) -> 24584 | M12: =(L12 + 'Lån Översikt'!$D$50) -> 46533 | N12: =IF('Lån Översikt'!$D$22 = "JA", IF(Q12 = TRUE, 'Lån Översikt'!$D$24 - M12, 'Lån Översikt'!$D$24 - M12 + 18300), 'Lån Översikt'!$D$24 - M12) -> 3267 | O12: =IF(G12 < 0.7*$G$4,TRUE, FALSE) -> FALSE | P12: =IF(G12 < 0.5*$G$4,TRUE, FALSE) -> FALSE | Q12: =IF(F11 < 7,TRUE, FALSE) -> FALSE
F13: 10 | G13: =(G12-J12) -> 3693750 | H13: =INT(IF(AND('Lån Översikt'!$D$7="JA", 'Lån Översikt'!$D$11="JA", 'Lån Översikt'!$D$8="JA"), (G13*(('Lån Översikt'!$C$7/100*'Lån Översikt'!$C$11/100)-'Lån Översikt'!$C$8/100))/12, IF(AND('Lån Översikt'!$D$7="JA", 'Lån Översikt'!$D$11="JA", 'Lån Översikt'!$D$8="NEJ"), (G13*(('Lån Översikt'!$C$7/100*'Lån Översikt'!$C$11/100))/12), 0))) -> 9440 | I13: =I12 -> 4712 | J13: =IF(AND(P13, O13), 0, IF(O13, INT((('Lån Översikt'!$C$5 * 1 / 100) / 12)), INT((('Lån Översikt'!$C$5 * 'Lån Översikt'!$C$15 / 100) / 12)))) -> 6250 | K13: =K12 -> 4166 | L13: =INT(SUM(H13:K13)) -> 24568 | M13: =(L13 + 'Lån Översikt'!$D$50) -> 46517 | N13: =IF('Lån Översikt'!$D$22 = "JA", IF(Q13 = TRUE, 'Lån Översikt'!$D$24 - M13, 'Lån Översikt'!$D$24 - M13 + 18300), 'Lån Översikt'!$D$24 - M13) -> 3283 | O13: =IF(G13 < 0.7*$G$4,TRUE, FALSE) -> FALSE | P13: =IF(G13 < 0.5*$G$4,TRUE, FALSE) -> FALSE | Q13: =IF(F12 < 7,TRUE, FALSE) -> FALSE
F14: 11 | G14: =(G13-J13) -> 3687500 | H14: =INT(IF(AND('Lån Översikt'!$D$7="JA", 'Lån Översikt'!$D$11="JA", 'Lån Översikt'!$D$8="JA"), (G14*(('Lån Översikt'!$C$7/100*'Lån Översikt'!$C$11/100)-'Lån Översikt'!$C$8/100))/12, IF(AND('Lån Översikt'!$D$7="JA", 'Lån Översikt'!$D$11="JA", 'Lån Översikt'!$D$8="NEJ"), (G14*(('Lån Översikt'!$C$7/100*'Lån Översikt'!$C$11/100))/12), 0))) -> 9424 | I14: =I13 -> 4712 | J14: =IF(AND(P14, O14), 0, IF(O14, INT((('Lån Översikt'!$C$5 * 1 / 100) / 12)), INT((('Lån Översikt'!$C$5 * 'Lån Översikt'!$C$15 / 100) / 12)))) -> 6250 | K14: =K13 -> 4166 | L14: =INT(SUM(H14:K14)) -> 24552 | M14: =(L14 + 'Lån Översikt'!$D$50) -> 46501 | N14: =IF('Lån Översikt'!$D$22 = "JA", IF(Q14 = TRUE, 'Lån Översikt'!$D$24 - M14, 'Lån Översikt'!$D$24 - M14 + 18300), 'Lån Översikt'!$D$24 - M14) -> 3299 | O14: =IF(G14 < 0.7*$G$4,TRUE, FALSE) -> FALSE | P14: =IF(G14 < 0.5*$G$4,TRUE, FALSE) -> FALSE | Q14: =IF(F13 < 7,TRUE, FALSE) -> FALSE
F15: 12 | G15: =(G14-J14) -> 3681250 | H15: =INT(IF(AND('Lån Översikt'!$D$7="JA", 'Lån Översikt'!$D$11="JA", 'Lån Översikt'!$D$8="JA"), (G15*(('Lån Översikt'!$C$7/100*'Lån Översikt'!$C$11/100)-'Lån Översikt'!$C$8/100))/12, IF(AND('Lån Översikt'!$D$7="JA", 'Lån Översikt'!$D$11="JA", 'Lån Översikt'!$D$8="NEJ"), (G15*(('Lån Översikt'!$C$7/100*'Lån Översikt'!$C$11/100))/12), 0))) -> 9408 | I15: =I14 -> 4712 | J15: =IF(AND(P15, O15), 0, IF(O15, INT((('Lån Översikt'!$C$5 * 1 / 100) / 12)), INT((('Lån Översikt'!$C$5 * 'Lån Översikt'!$C$15 / 100) / 12)))) -> 6250 | K15: =K14 -> 4166 | L15: =INT(SUM(H15:K15)) -> 24536 | M15: =(L15 + 'Lån Översikt'!$D$50) -> 46485 | N15: =IF('Lån Översikt'!$D$22 = "JA", IF(Q15 = TRUE, 'Lån Översikt'!$D$24 - M15, 'Lån Översikt'!$D$24 - M15 + 18300), 'Lån Översikt'!$D$24 - M15) -> 3315 | O15: =IF(G15 < 0.7*$G$4,TRUE, FALSE) -> FALSE | P15: =IF(G15 < 0.5*$G$4,TRUE, FALSE) -> FALSE | Q15: =IF(F14 < 7,TRUE, FALSE) -> FALSE
F16: 13 | G16: =(G15-J15) -> 3675000 | H16: =INT(IF(AND('Lån Översikt'!$D$7="JA", 'Lån Översikt'!$D$11="JA", 'Lån Översikt'!$D$8="JA"), (G16*(('Lån Översikt'!$C$7/100*'Lån Översikt'!$C$11/100)-'Lån Översikt'!$C$8/100))/12, IF(AND('Lån Översikt'!$D$7="JA", 'Lån Översikt'!$D$11="JA", 'Lån Översikt'!$D$8="NEJ"), (G16*(('Lån Översikt'!$C$7/100*'Lån Översikt'!$C$11/100))/12), 0))) -> 9392 | I16: =I15 -> 4712 | J16: =IF(AND(P16, O16), 0, IF(O16, INT((('Lån Översikt'!$C$5 * 1 / 100) / 12)), INT((('Lån Översikt'!$C$5 * 'Lån Översikt'!$C$15 / 100) / 12)))) -> 6250 | K16: =K15 -> 4166 | L16: =INT(SUM(H16:K16)) -> 24520 | M16: =(L16 + 'Lån Översikt'!$D$50) -> 46469 | N16: =IF('Lån Översikt'!$D$22 = "JA", IF(Q16 = TRUE, 'Lån Översikt'!$D$24 - M16, 'Lån Översikt'!$D$24 - M16 + 18300), 'Lån Översikt'!$D$24 - M16) -> 3331 | O16: =IF(G16 < 0.7*$G$4,TRUE, FALSE) -> FALSE | P16: =IF(G16 < 0.5*$G$4,TRUE, FALSE) -> FALSE | Q16: =IF(F15 < 7,TRUE, FALSE) -> FALSE
... F21: 18 | G21: =(G20-J20) -> 3643750 | H21: =INT(IF(AND('Lån Översikt'!$D$7="JA", 'Lån Översikt'!$D$11="JA", 'Lån Översikt'!$D$8="JA"), (G21*(('Lån Översikt'!$C$7/100*'Lån Översikt'!$C$11/100)-'Lån Översikt'!$C$8/100))/12, IF(AND('Lån Översikt'!$D$7="JA", 'Lån Översikt'!$D$11="JA", 'Lån Översikt'!$D$8="NEJ"), (G21*(('Lån Översikt'!$C$7/100*'Lån Översikt'!$C$11/100))/12), 0))) -> 9312 | I21: =I20 -> 4712 | J21: =IF(AND(P21, O21), 0, IF(O21, INT((('Lån Översikt'!$C$5 * 1 / 100) / 12)), INT((('Lån Översikt'!$C$5 * 'Lån Översikt'!$C$15 / 100) / 12)))) -> 6250 | K21: =K20 -> 4166 | L21: =INT(SUM(H21:K21)) -> 24440 | M21: =(L21 + 'Lån Översikt'!$D$50) -> 46389 | N21: =IF('Lån Översikt'!$D$22 = "JA", IF(Q21 = TRUE, 'Lån Översikt'!$D$24 - M21, 'Lån Översikt'!$D$24 - M21 + 18300), 'Lån Översikt'!$D$24 - M21) -> 3411 | O21: =IF(G21 < 0.7*$G$4,TRUE, FALSE) -> FALSE | P21: =IF(G21 < 0.5*$G$4,TRUE, FALSE) -> FALSE | Q21: =IF(F20 < 7,TRUE, FALSE) -> FALSE
F22: 19 | G22: =(G21-J21) -> 3637500 | H22: =INT(IF(AND('Lån Översikt'!$D$7="JA", 'Lån Översikt'!$D$11="JA", 'Lån Översikt'!$D$8="JA"), (G22*(('Lån Översikt'!$C$7/100*'Lån Översikt'!$C$11/100)-'Lån Översikt'!$C$8/100))/12, IF(AND('Lån Översikt'!$D$7="JA", 'Lån Översikt'!$D$11="JA", 'Lån Översikt'!$D$8="NEJ"), (G22*(('Lån Översikt'!$C$7/100*'Lån Översikt'!$C$11/100))/12), 0))) -> 9296 | I22: =I21 -> 4712 | J22: =IF(AND(P22, O22), 0, IF(O22, INT((('Lån Översikt'!$C$5 * 1 / 100) / 12)), INT((('Lån Översikt'!$C$5 * 'Lån Översikt'!$C$15 / 100) / 12)))) -> 6250 | K22: =K21 -> 4166 | L22: =INT(SUM(H22:K22)) -> 24424 | M22: =(L22 + 'Lån Översikt'!$D$50) -> 46373 | N22: =IF('Lån Översikt'!$D$22 = "JA", IF(Q22 = TRUE, 'Lån Översikt'!$D$24 - M22, 'Lån Översikt'!$D$24 - M22 + 18300), 'Lån Översikt'!$D$24 - M22) -> 3427 | O22: =IF(G22 < 0.7*$G$4,TRUE, FALSE) -> FALSE | P22: =IF(G22 < 0.5*$G$4,TRUE, FALSE) -> FALSE | Q22: =IF(F21 < 9,TRUE, FALSE) -> FALSE
F23: 20 | G23: =(G22-J22) -> 3631250 | H23: =INT(IF(AND('Lån Översikt'!$D$7="JA", 'Lån Översikt'!$D$11="JA", 'Lån Översikt'!$D$8="JA"), (G23*(('Lån Översikt'!$C$7/100*'Lån Översikt'!$C$11/100)-'Lån Översikt'!$C$8/100))/12, IF(AND('Lån Översikt'!$D$7="JA", 'Lån Översikt'!$D$11="JA", 'Lån Översikt'!$D$8="NEJ"), (G23*(('Lån Översikt'!$C$7/100*'Lån Översikt'!$C$11/100))/12), 0))) -> 9280 | I23: =I22 -> 4712 | J23: =IF(AND(P23, O23), 0, IF(O23, INT((('Lån Översikt'!$C$5 * 1 / 100) / 12)), INT((('Lån Översikt'!$C$5 * 'Lån Översikt'!$C$15 / 100) / 12)))) -> 6250 | K23: =K22 -> 4166 | L23: =INT(SUM(H23:K23)) -> 24408 | M23: =(L23 + 'Lån Översikt'!$D$50) -> 46357 | N23: =IF('Lån Översikt'!$D$22 = "JA", IF(Q23 = TRUE, 'Lån Översikt'!$D$24 - M23, 'Lån Översikt'!$D$24 - M23 + 18300), 'Lån Översikt'!$D$24 - M23) -> 3443 | O23: =IF(G23 < 0.7*$G$4,TRUE, FALSE) -> FALSE | P23: =IF(G23 < 0.5*$G$4,TRUE, FALSE) -> FALSE | Q23: =IF(F22 < 9,TRUE, FALSE) -> FALSE
F24: 21 | G24: =(G23-J23) -> 3625000 | H24: =INT(IF(AND('Lån Översikt'!$D$7="JA", 'Lån Översikt'!$D$11="JA", 'Lån Översikt'!$D$8="JA"), (G24*(('Lån Översikt'!$C$7/100*'Lån Översikt'!$C$11/100)-'Lån Översikt'!$C$8/100))/12, IF(AND('Lån Översikt'!$D$7="JA", 'Lån Översikt'!$D$11="JA", 'Lån Översikt'!$D$8="NEJ"), (G24*(('Lån Översikt'!$C$7/100*'Lån Översikt'!$C$11/100))/12), 0))) -> 9264 | I24: =I23 -> 4712 | J24: =IF(AND(P24, O24), 0, IF(O24, INT((('Lån Översikt'!$C$5 * 1 / 100) / 12)), INT((('Lån Översikt'!$C$5 * 'Lån Översikt'!$C$15 / 100) / 12)))) -> 6250 | K24: =K23 -> 4166 | L24: =INT(SUM(H24:K24)) -> 24392 | M24: =(L24 + 'Lån Översikt'!$D$50) -> 46341 | N24: =IF('Lån Översikt'!$D$22 = "JA", IF(Q24 = TRUE, 'Lån Översikt'!$D$24 - M24, 'Lån Översikt'!$D$24 - M24 + 18300), 'Lån Översikt'!$D$24 - M24) -> 3459 | O24: =IF(G24 < 0.7*$G$4,TRUE, FALSE) -> FALSE | P24: =IF(G24 < 0.5*$G$4,TRUE, FALSE) -> FALSE | Q24: =IF(F23 < 9,TRUE, FALSE) -> FALSE
F25: 22 | G25: =(G24-J24) -> 3618750 | H25: =INT(IF(AND('Lån Översikt'!$D$7="JA", 'Lån Översikt'!$D$11="JA", 'Lån Översikt'!$D$8="JA"), (G25*(('Lån Översikt'!$C$7/100*'Lån Översikt'!$C$11/100)-'Lån Översikt'!$C$8/100))/12, IF(AND('Lån Översikt'!$D$7="JA", 'Lån Översikt'!$D$11="JA", 'Lån Översikt'!$D$8="NEJ"), (G25*(('Lån Översikt'!$C$7/100*'Lån Översikt'!$C$11/100))/12), 0))) -> 9248 | I25: =I24 -> 4712 | J25: =IF(AND(P25, O25), 0, IF(O25, INT((('Lån Översikt'!$C$5 * 1 / 100) / 12)), INT((('Lån Översikt'!$C$5 * 'Lån Översikt'!$C$15 / 100) / 12)))) -> 6250 | K25: =K24 -> 4166 | L25: =INT(SUM(H25:K25)) -> 24376 | M25: =(L25 + 'Lån Översikt'!$D$50) -> 46325 | N25: =IF('Lån Översikt'!$D$22 = "JA", IF(Q25 = TRUE, 'Lån Översikt'!$D$24 - M25, 'Lån Översikt'!$D$24 - M25 + 18300), 'Lån Översikt'!$D$24 - M25) -> 3475 | O25: =IF(G25 < 0.7*$G$4,TRUE, FALSE) -> FALSE | P25: =IF(G25 < 0.5*$G$4,TRUE, FALSE) -> FALSE | Q25: =IF(F24 < 9,TRUE, FALSE) -> FALSE
F26: 23 | G26: =(G25-J25) -> 3612500 | H26: =INT(IF(AND('Lån Översikt'!$D$7="JA", 'Lån Översikt'!$D$11="JA", 'Lån Översikt'!$D$8="JA"), (G26*(('Lån Översikt'!$C$7/100*'Lån Översikt'!$C$11/100)-'Lån Översikt'!$C$8/100))/12, IF(AND('Lån Översikt'!$D$7="JA", 'Lån Översikt'!$D$11="JA", 'Lån Översikt'!$D$8="NEJ"), (G26*(('Lån Översikt'!$C$7/100*'Lån Översikt'!$C$11/100))/12), 0))) -> 9232 | I26: =I25 -> 4712 | J26: =IF(AND(P26, O26), 0, IF(O26, INT((('Lån Översikt'!$C$5 * 1 / 100) / 12)), INT((('Lån Översikt'!$C$5 * 'Lån Översikt'!$C$15 / 100) / 12)))) -> 6250 | K26: =K25 -> 4166 | L26: =INT(SUM(H26:K26)) -> 24360 | M26: =(L26 + 'Lån Översikt'!$D$50) -> 46309 | N26: =IF('Lån Översikt'!$D$22 = "JA", IF(Q26 = TRUE, 'Lån Översikt'!$D$24 - M26, 'Lån Översikt'!$D$24 - M26 + 18300), 'Lån Översikt'!$D$24 - M26) -> 3491 | O26: =IF(G26 < 0.7*$G$4,TRUE, FALSE) -> FALSE | P26: =IF(G26 < 0.5*$G$4,TRUE, FALSE) -> FALSE | Q26: =IF(F25 < 9,TRUE, FALSE) -> FALSE
F27: 24 | G27: =(G26-J26) -> 3606250 | H27: =INT(IF(AND('Lån Översikt'!$D$7="JA", 'Lån Översikt'!$D$11="JA", 'Lån Översikt'!$D$8="JA"), (G27*(('Lån Översikt'!$C$7/100*'Lån Översikt'!$C$11/100)-'Lån Översikt'!$C$8/100))/12, IF(AND('Lån Översikt'!$D$7="JA", 'Lån Översikt'!$D$11="JA", 'Lån Översikt'!$D$8="NEJ"), (G27*(('Lån Översikt'!$C$7/100*'Lån Översikt'!$C$11/100))/12), 0))) -> 9216 | I27: =I26 -> 4712 | J27: =IF(AND(P27, O27), 0, IF(O27, INT((('Lån Översikt'!$C$5 * 1 / 100) / 12)), INT((('Lån Översikt'!$C$5 * 'Lån Översikt'!$C$15 / 100) / 12)))) -> 6250 | K27: =K26 -> 4166 | L27: =INT(SUM(H27:K27)) -> 24344 | M27: =(L27 + 'Lån Översikt'!$D$50) -> 46293 | N27: =IF('Lån Översikt'!$D$22 = "JA", IF(Q27 = TRUE, 'Lån Översikt'!$D$24 - M27, 'Lån Översikt'!$D$24 - M27 + 18300), 'Lån Översikt'!$D$24 - M27) -> 3507 | O27: =IF(G27 < 0.7*$G$4,TRUE, FALSE) -> FALSE | P27: =IF(G27 < 0.5*$G$4,TRUE, FALSE) -> FALSE | Q27: =IF(F26 < 9,TRUE, FALSE) -> FALSE
F28: 25 | G28: =(G27-J27) -> 3600000 | H28: =INT(IF(AND('Lån Översikt'!$D$7="JA", 'Lån Översikt'!$D$11="JA", 'Lån Översikt'!$D$8="JA"), (G28*(('Lån Översikt'!$C$7/100*'Lån Översikt'!$C$11/100)-'Lån Översikt'!$C$8/100))/12, IF(AND('Lån Översikt'!$D$7="JA", 'Lån Översikt'!$D$11="JA", 'Lån Översikt'!$D$8="NEJ"), (G28*(('Lån Översikt'!$C$7/100*'Lån Översikt'!$C$11/100))/12), 0))) -> 9201 | I28: =I27 -> 4712 | J28: =IF(AND(P28, O28), 0, IF(O28, INT((('Lån Översikt'!$C$5 * 1 / 100) / 12)), INT((('Lån Översikt'!$C$5 * 'Lån Översikt'!$C$15 / 100) / 12)))) -> 6250 | K28: =K27 -> 4166 | L28: =INT(SUM(H28:K28)) -> 24329 | M28: =(L28 + 'Lån Översikt'!$D$50) -> 46278 | N28: =IF('Lån Översikt'!$D$22 = "JA", IF(Q28 = TRUE, 'Lån Översikt'!$D$24 - M28, 'Lån Översikt'!$D$24 - M28 + 18300), 'Lån Översikt'!$D$24 - M28) -> 3522 | O28: =IF(G28 < 0.7*$G$4,TRUE, FALSE) -> FALSE | P28: =IF(G28 < 0.5*$G$4,TRUE, FALSE) -> FALSE | Q28: =IF(F27 < 9,TRUE, FALSE) -> FALSE
F29: 26 | G29: =(G28-J28) -> 3593750 | H29: =INT(IF(AND('Lån Översikt'!$D$7="JA", 'Lån Översikt'!$D$11="JA", 'Lån Översikt'!$D$8="JA"), (G29*(('Lån Översikt'!$C$7/100*'Lån Översikt'!$C$11/100)-'Lån Översikt'!$C$8/100))/12, IF(AND('Lån Översikt'!$D$7="JA", 'Lån Översikt'!$D$11="JA", 'Lån Översikt'!$D$8="NEJ"), (G29*(('Lån Översikt'!$C$7/100*'Lån Översikt'!$C$11/100))/12), 0))) -> 9185 | I29: =I28 -> 4712 | J29: =IF(AND(P29, O29), 0, IF(O29, INT((('Lån Översikt'!$C$5 * 1 / 100) / 12)), INT((('Lån Översikt'!$C$5 * 'Lån Översikt'!$C$15 / 100) / 12)))) -> 6250 | K29: =K28 -> 4166 | L29: =INT(SUM(H29:K29)) -> 24313 | M29: =(L29 + 'Lån Översikt'!$D$50) -> 46262 | N29: =IF('Lån Översikt'!$D$22 = "JA", IF(Q29 = TRUE, 'Lån Översikt'!$D$24 - M29, 'Lån Översikt'!$D$24 - M29 + 18300), 'Lån Översikt'!$D$24 - M29) -> 3538 | O29: =IF(G29 < 0.7*$G$4,TRUE, FALSE) -> FALSE | P29: =IF(G29 < 0.5*$G$4,TRUE, FALSE) -> FALSE | Q29: =IF(F28 < 9,TRUE, FALSE) -> FALSE
F30: 27 | G30: =(G29-J29) -> 3587500 | H30: =INT(IF(AND('Lån Översikt'!$D$7="JA", 'Lån Översikt'!$D$11="JA", 'Lån Översikt'!$D$8="JA"), (G30*(('Lån Översikt'!$C$7/100*'Lån Översikt'!$C$11/100)-'Lån Översikt'!$C$8/100))/12, IF(AND('Lån Översikt'!$D$7="JA", 'Lån Översikt'!$D$11="JA", 'Lån Översikt'!$D$8="NEJ"), (G30*(('Lån Översikt'!$C$7/100*'Lån Översikt'!$C$11/100))/12), 0))) -> 9169 | I30: =I29 -> 4712 | J30: =IF(AND(P30, O30), 0, IF(O30, INT((('Lån Översikt'!$C$5 * 1 / 100) / 12)), INT((('Lån Översikt'!$C$5 * 'Lån Översikt'!$C$15 / 100) / 12)))) -> 6250 | K30: =K29 -> 4166 | L30: =INT(SUM(H30:K30)) -> 24297 | M30: =(L30 + 'Lån Översikt'!$D$50) -> 46246 | N30: =IF('Lån Översikt'!$D$22 = "JA", IF(Q30 = TRUE, 'Lån Översikt'!$D$24 - M30, 'Lån Översikt'!$D$24 - M30 + 18300), 'Lån Översikt'!$D$24 - M30) -> 3554 | O30: =IF(G30 < 0.7*$G$4,TRUE, FALSE) -> FALSE | P30: =IF(G30 < 0.5*$G$4,TRUE, FALSE) -> FALSE | Q30: =IF(F29 < 9,TRUE, FALSE) -> FALSE
F31: 28 | G31: =(G30-J30) -> 3581250 | H31: =INT(IF(AND('Lån Översikt'!$D$7="JA", 'Lån Översikt'!$D$11="JA", 'Lån Översikt'!$D$8="JA"), (G31*(('Lån Översikt'!$C$7/100*'Lån Översikt'!$C$11/100)-'Lån Översikt'!$C$8/100))/12, IF(AND('Lån Översikt'!$D$7="JA", 'Lån Översikt'!$D$11="JA", 'Lån Översikt'!$D$8="NEJ"), (G31*(('Lån Översikt'!$C$7/100*'Lån Översikt'!$C$11/100))/12), 0))) -> 9153 | I31: =I30 -> 4712 | J31: =IF(AND(P31, O31), 0, IF(O31, INT((('Lån Översikt'!$C$5 * 1 / 100) / 12)), INT((('Lån Översikt'!$C$5 * 'Lån Översikt'!$C$15 / 100) / 12)))) -> 6250 | K31: =K30 -> 4166 | L31: =INT(SUM(H31:K31)) -> 24281 | M31: =(L31 + 'Lån Översikt'!$D$50) -> 46230 | N31: =IF('Lån Översikt'!$D$22 = "JA", IF(Q31 = TRUE, 'Lån Översikt'!$D$24 - M31, 'Lån Översikt'!$D$24 - M31 + 18300), 'Lån Översikt'!$D$24 - M31) -> 3570 | O31: =IF(G31 < 0.7*$G$4,TRUE, FALSE) -> FALSE | P31: =IF(G31 < 0.5*$G$4,TRUE, FALSE) -> FALSE | Q31: =IF(F30 < 9,TRUE, FALSE) -> FALSE
F32: 29 | G32: =(G31-J31) -> 3575000 | H32: =INT(IF(AND('Lån Översikt'!$D$7="JA", 'Lån Översikt'!$D$11="JA", 'Lån Översikt'!$D$8="JA"), (G32*(('Lån Översikt'!$C$7/100*'Lån Översikt'!$C$11/100)-'Lån Översikt'!$C$8/100))/12, IF(AND('Lån Översikt'!$D$7="JA", 'Lån Översikt'!$D$11="JA", 'Lån Översikt'!$D$8="NEJ"), (G32*(('Lån Översikt'!$C$7/100*'Lån Översikt'!$C$11/100))/12), 0))) -> 9137 | I32: =I31 -> 4712 | J32: =IF(AND(P32, O32), 0, IF(O32, INT((('Lån Översikt'!$C$5 * 1 / 100) / 12)), INT((('Lån Översikt'!$C$5 * 'Lån Översikt'!$C$15 / 100) / 12)))) -> 6250 | K32: =K31 -> 4166 | L32: =INT(SUM(H32:K32)) -> 24265 | M32: =(L32 + 'Lån Översikt'!$D$50) -> 46214 | N32: =IF('Lån Översikt'!$D$22 = "JA", IF(Q32 = TRUE, 'Lån Översikt'!$D$24 - M32, 'Lån Översikt'!$D$24 - M32 + 18300), 'Lån Översikt'!$D$24 - M32) -> 3586 | O32: =IF(G32 < 0.7*$G$4,TRUE, FALSE) -> FALSE | P32: =IF(G32 < 0.5*$G$4,TRUE, FALSE) -> FALSE | Q32: =IF(F31 < 9,TRUE, FALSE) -> FALSE
F33: 30 | G33: =(G32-J32) -> 3568750 | H33: =INT(IF(AND('Lån Översikt'!$D$7="JA", 'Lån Översikt'!$D$11="JA", 'Lån Översikt'!$D$8="JA"), (G33*(('Lån Översikt'!$C$7/100*'Lån Översikt'!$C$11/100)-'Lån Översikt'!$C$8/100))/12, IF(AND('Lån Översikt'!$D$7="JA", 'Lån Översikt'!$D$11="JA", 'Lån Översikt'!$D$8="NEJ"), (G33*(('Lån Översikt'!$C$7/100*'Lån Översikt'!$C$11/100))/12), 0))) -> 9121 | I33: =I32 -> 4712 | J33: =IF(AND(P33, O33), 0, IF(O33, INT((('Lån Översikt'!$C$5 * 1 / 100) / 12)), INT((('Lån Översikt'!$C$5 * 'Lån Översikt'!$C$15 / 100) / 12)))) -> 6250 | K33: =K32 -> 4166 | L33: =INT(SUM(H33:K33)) -> 24249 | M33: =(L33 + 'Lån Översikt'!$D$50) -> 46198 | N33: =IF('Lån Översikt'!$D$22 = "JA", IF(Q33 = TRUE, 'Lån Översikt'!$D$24 - M33, 'Lån Översikt'!$D$24 - M33 + 18300), 'Lån Översikt'!$D$24 - M33) -> 3602 | O33: =IF(G33 < 0.7*$G$4,TRUE, FALSE) -> FALSE | P33: =IF(G33 < 0.5*$G$4,TRUE, FALSE) -> FALSE | Q33: =IF(F32 < 9,TRUE, FALSE) -> FALSE
... F604: 601 | G604: =(G603-J603) -> 1871875 | H604: =INT(IF(AND('Lån Översikt'!$D$7="JA", 'Lån Översikt'!$D$11="JA", 'Lån Översikt'!$D$8="JA"), (G604*(('Lån Översikt'!$C$7/100*'Lån Översikt'!$C$11/100)-'Lån Översikt'!$C$8/100))/12, IF(AND('Lån Översikt'!$D$7="JA", 'Lån Översikt'!$D$11="JA", 'Lån Översikt'!$D$8="NEJ"), (G604*(('Lån Översikt'!$C$7/100*'Lån Översikt'!$C$11/100))/12), 0))) -> 4784 | I604: =I603 -> 4712 | J604: =IF(AND(P604, O604), 0, IF(O604, INT((('Lån Översikt'!$C$5 * 1 / 100) / 12)), INT((('Lån Översikt'!$C$5 * 'Lån Översikt'!$C$15 / 100) / 12)))) -> 0 | K604: =K603 -> 4166 | L604: =INT(SUM(H604:K604)) -> 13662 | M604: =(L604 + 'Lån Översikt'!$D$50) -> 35611 | N604: =IF('Lån Översikt'!$D$22 = "JA", IF(Q604 = TRUE, 'Lån Översikt'!$D$24 - M604, 'Lån Översikt'!$D$24 - M604 + 18300), 'Lån Översikt'!$D$24 - M604) -> 14189 | O604: =IF(G604 < 0.7*$G$4,TRUE, FALSE) -> TRUE | P604: =IF(G604 < 0.5*$G$4,TRUE, FALSE) -> TRUE | Q604: =IF(F603 < 9,TRUE, FALSE) -> FALSE

Sheet Räntekalkylator
B2: Deta upp lån och räkna ut ränta | E2: Nordea | F2: Listränta | G2: Rabatt | H2: Slutränta
B3: Antal låndelar | C3: 4 | E3: Ränta rörlig 3 mån (%) | F3: 4.54 | G3: 1.3 | H3: =(F3-G3) -> 3.24
B4: Skattereduktion | C4: 70 | E4: Ränta 1 år (%) | F4: 3.73 | G4: 0.8 | H4: =(F4-G4) -> 2.93
B5: Antal rörlig | C5: 2 | E5: Ränta 2 år (%) | F5: 3.63 | G5: 0.6 | H5: =(F5-G5) -> 3.03
B6: Antal 1 år | C6: 0 | E6: Ränta 5 år (%) | F6: 3.68 | G6: 0 | H6: =(F6-G6) -> 3.68
B7: Antal 2 år | C7: 2
B8: Antal 5 år | C8: 0 | E8: Kombination Räntor | F8: Pris/Mån (inkl. skattereduktion) | G8: Pris/Mån (exkl. skattereduktion) | H8: Slutränta
B9: Medelvärde (%) | C9: =SUM(C5*H3, C6*H4, C7*H5, C8*H6)/C3 -> 3.135 | E9: 4x 1år | F9: 6409 | G9: 9165 | H9: 2.93
B10: Pris/Mån (inkl. skattereduktion) | C10: =INT(IF(AND('Lån Översikt'!$D$7="JA", 'Lån Översikt'!$D$11="JA", 'Lån Översikt'!$D$8="JA"), ('Lån Översikt'!C5*((C9/100*C4/100)-'Lån Översikt'!$C$8/100))/12, IF(AND('Lån Översikt'!$D$7="JA", 'Lån Översikt'!$D$11="JA", 'Lån Översikt'!$D$8="NEJ"), ('Lån Översikt'!C5*((C9/100*C4/100))/12), 0))) -> 6857 | E10: 1x rörligt + 3x 1år | F10: 6578 | G10: 9398 | H10: 3.0075
B11: Pris/Mån (exkl. skattereduktion) | C11: =INT(IF(AND('Lån Översikt'!$D$7="JA", 'Lån Översikt'!$D$11="JA", 'Lån Översikt'!$D$8="JA"), ('Lån Översikt'!C5*((C9/100*(C4+30)/100)-'Lån Översikt'!$C$8/100))/12, IF(AND('Lån Översikt'!$D$7="JA", 'Lån Översikt'!$D$11="JA", 'Lån Översikt'!$D$8="NEJ"), ('Lån Översikt'!C5*((C9/100*(C4+30)/100))/12), 0))) -> 9796 | E11: 1x Rörligt + 2x 1 år | F11: 6635 | G11: 9479 | H11: 3.033
E12: 2x Rörligt + 1x 1år | F12: 6861 | G12: 9802 | H12: 3.137
E13: 1x Rörligt + 1 1år + 1 2år | F13: 6708 | G13: 9583 | H13: 3.067
E14: 1x Rörligt + 3x 2år | F14: 6742 | G14: 9632 | H14: 3.0825
E15: 2x Rörligt + 2x 1år | F15: 6748 | G15: 9640 | H15: 3.085
E16: 1x Rörligt + 2x 2år | F16: 6781 | G16: 9687 | H16: 3.1
E17: 2x rörligt + 2x 2år | F17: 6857 | G17: 9769 | H17: 3.135

Sheet Verisure kodord 
A1: Verisure: | B1: Gymnastik
B2: Nederländarna

Sheet Inför flytt 
A1: Att köpa inför flytt: | B1: Länk:
A2: Ved | B2: https://www.jula.se/catalog/bygg-och-farg/varme-och-ventilation/kaminer-och-oppna-spisar/fasta-branslen/ved-023627/
A3: Grindar | B3: https://www.babyworld.se/sv/varumarken/babydan/babydan-liva-multidan-grind-metall-vit?gad_source=1&gbraid=0AAAAADMjSNFdICtHsu0mz_a79jwqRTFEL&gclid=CjwKCAiA9IC6BhA3EiwAsbltOL5JBsbom1jATHu2oG82MeXIAO7L4lU_c4FUCWUxS5TLCpXaJvvcvBoCxGEQAvD_BwE&gclsrc=aw.ds
A4: Lampor
A5: Stege
A6: Säkringar
A7: Mattor
A8: Förvaringslådor inne
A9: Förvaring garage
A10: Krokar
A11: Robotdammsugare
A12: Robotgräsklippare
A13: Snöskyffel
A14: Skruvar/muttrar
A15: Förvaring kök
... A19: Gasolvärmare altan
A20: Lampknappar | B20: https://www.bauhaus.se/strombrytare-tem-10ax-kron-svart?gad_source=1&gbraid=0AAAAADxd_kzzYOS-uzo1bvf1izxK94CGj&gclid=CjwKCAiApsm7BhBZEiwAvIu2X9P-Rx2l3jCP3J0qz-pevrEwvlnyqJYr-V_WvHywmPnFHW9K3Tl13hoCyNAQAvD_BwE
A21: Dörr till sovrum uppe | B21: https://www.byggmax.se/innerdörr-villa-210#1233=107492
A22: Vägguttag | B22: https://www.byggmax.se/vägguttag-optima-2-vägs-malmbergs-p6334075?gad_source=1&gbraid=0AAAAAD8WC3H9OI-2S8rEDdG5s8lv4oRbi&gclid=CjwKCAiApsm7BhBZEiwAvIu2X_C7inXz_KJFV5Dmd6FhjH4_9UOyTjzeUlOrknvRBeyHll2SsFNqDBoC_KIQAvD_BwE#913=78207
A23: Blandare badrum
A24: Tvåsitssoffa hall uppe | B24: https://www.ikea.com/se/sv/p/lillehem-2-sitsig-modulsoffa-vissle-beige-metall-s19471279/
A25: Nya köksredskap (slevar etc.)
A26: Bra skärbräda i trä
A27: Minst en bra kniv
A28: Knivslip
A29: Nya saxar
A30: Dörrar övervåning
A31: Garderobsdörrar
A32: Matbord kök (runt)
A33: Matbord matsal
A34: Puffar ovanvåning
A35: TV
A36: Stekpanna rostfritt stål
... A38: Tv bänk

Sheet Överföringar
B2: År | C2: Månad | D2: Husutgifter | E2: Ica-kort | F2: Markus nettolön | G2: Majas Nettolön | H2: Netto total | I2: Maja Andel | J2: Markus Andel | K2: Huskonto Maja | L2: Ica-kort Maja | M2: Huskonto Markus | N2: Ica-kort Markus | O2: Total Huskonto | P2: Total Ica-kort
B3: 2025 | C3: April | D3: =Data!L5 -> 24696 | E3: 8331 | I3: 0.65 | J3: 0.35 | K3: =INT(D4*0.65) -> 16042 | L3: =INT(8331*0.65) -> 5415 | M3: =INT(D4*0.35) -> 8638 | N3: =INT(8331*0.35) -> 2915 | O3: =SUM(K3,M3) -> 24680 | P3: =SUM(L3,N3) -> 8330
B4: 2025 | C4: Maj | D4: =Data!L6 -> 24680 | E4: 8331 | I4: 0.65 | J4: 0.35 | K4: =INT(D5*0.65) -> 16031 | L4: =INT(8331*0.65) -> 5415 | M4: =INT(D5*0.35) -> 8632 | N4: =INT(8331*0.35) -> 2915 | O4: =SUM(K4,M4) -> 24663 | P4: =SUM(L4,N4) -> 8330
B5: 2025 | C5: Juni | D5: =Data!L7 -> 24664 | E5: 8331 | I5: 0.65 | J5: 0.35 | K5: =INT(D6*0.65) -> 16021 | L5: =INT(8331*0.65) -> 5415 | M5: =INT(D6*0.35) -> 8626 | N5: =INT(8331*0.35) -> 2915 | O5: =SUM(K5,M5) -> 24647 | P5: =SUM(L5,N5) -> 8330
B6: 2025 | C6: Juli | D6: =Data!L8 -> 24648 | E6: 8331 | I6: 0.65 | J6: 0.35 | K6: =INT(D7*0.65) -> 16010 | L6: =INT(8331*0.65) -> 5415 | M6: =INT(D7*0.35) -> 8621 | N6: =INT(8331*0.35) -> 2915 | O6: =SUM(K6,M6) -> 24631 | P6: =SUM(L6,N6) -> 8330
B7: 2025 | C7: Augusti | D7: =Data!L9 -> 24632 | E7: 8331 | I7: 0.65 | J7: 0.35 | K7: =INT(D8*0.65) -> 16000 | L7: =INT(8331*0.65) -> 5415 | M7: =INT(D8*0.35) -> 8615 | N7: =INT(8331*0.35) -> 2915 | O7: =SUM(K7,M7) -> 24615 | P7: =SUM(L7,N7) -> 8330
B8: 2025 | C8: September | D8: =Data!L10 -> 24616 | E8: 8331 | I8: 0.65 | J8: 0.35 | K8: =INT(D8*I8) -> 16000 | L8: =INT(8331*0.65) -> 5415 | M8: =INT(D9*0.35) -> 8610 | N8: =INT(8331*0.35) -> 2915 | O8: =SUM(K8,M8) -> 24610 | P8: =SUM(L8,N8) -> 8330
B9: 2025 | C9: Oktober | D9: =Data!L11 -> 24600 | E9: 8331 | I9: 0.416 | J9: 0.584 | K9: =INT(D9*I9) -> 10233 | L9: =INT(8331*I9) -> 3465 | M9: =INT(D9*J9) -> 14366 | N9: =INT(8331*J9) -> 4865 | O9: =SUM(K9,M9) -> 24599 | P9: =SUM(L9,N9) -> 8330
B10: 2025 | C10: November | D10: =Data!L12 -> 24584 | E10: 8331 | I10: 0.45358 | J10: 0.5464 | K10: =INT(D10*I10) -> 11150 | L10: =INT(8331*I10) -> 3778 | M10: =INT(D10*J10) -> 13432 | N10: =INT(8331*J10) -> 4552 | O10: =SUM(K10,M10) -> 24582 | P10: =SUM(L10,N10) -> 8330
B11: 2025 | C11: December | D11: =Data!L13 -> 24568 | E11: 8331 | I11: 0.435 | J11: =1-I11 -> 0.565 | K11: =INT(D11*I11) -> 10687 | L11: =INT(8331*I11) -> 3623 | M11: =INT(D11*J11) -> 13880 | N11: =INT(8331*J11) -> 4707 | O11: =SUM(K11,M11) -> 24567 | P11: =SUM(L11,N11) -> 8330
B12: 2026 | C12: Januari | D12: =Data!L14 -> 24552 | E12: 8331 | F12: 30844 | G12: 26232 | H12: =SUM(F12:G12) -> 57076 | I12: =G12/H12 -> 0.45959773 | J12: =F12/H12 -> 0.54040227 | K12: =INT(D12*I12) -> 11284 | L12: =INT(E12*I12) -> 3828 | M12: =INT(D12*J12) -> 13267 | N12: =INT(E12*J12) -> 4502 | O12: =SUM(K12,M12) -> 24551 | P12: =SUM(L12,N12) -> 8330
B13: 2026 | C13: Februari | D13: =Data!L15 + 'Lån Översikt'!D55 -> 27235 | E13: 8331 | F13: =37288+5632 -> 42920 | G13: 14024 | H13: =SUM(F13:G13) -> 56944 | I13: =G13/H13 -> 0.24627704 | J13: =F13/H13 -> 0.75372296 | K13: =INT(D13*I13) -> 6707 | L13: =INT(E13*I13) -> 2051 | M13: =INT(D13*J13) -> 20527 | N13: =INT(E13*J13) -> 6279 | O13: =SUM(K13,M13) -> 27234 | P13: =SUM(L13,N13) -> 8330
B14: 2026 | C14: Mars | D14: =Data!L16 + 'Lån Översikt'!D55 -> 27219 | E14: 8331 | F14: 35974 | G14: 12194 | H14: =SUM(F14:G14) -> 48168 | I14: =G14/H14 -> 0.25315562 | J14: =F14/H14 -> 0.74684438 | K14: =INT(D14*I14) -> 6890 | L14: =INT(E14*I14) -> 2109 | M14: =INT(D14*J14) -> 20328 | N14: =INT(E14*J14) -> 6221 | O14: =SUM(K14,M14) -> 27218 | P14: =SUM(L14,N14) -> 8330
B15: 2026 | C15: April | D15: =Data!L17 + 'Lån Översikt'!D55 -> 27203 | E15: 8331 | F15: 37288 | G15: 12804 | H15: =SUM(F15:G15) -> 50092 | I15: =G15/H15 -> 0.25560968 | J15: =F15/H15 -> 0.74439032 | K15: =INT(D15*I15) -> 6953 | L15: =INT(E15*I15) -> 2129 | M15: =INT(D15*J15) -> 20249 | N15: =INT(E15*J15) -> 6201 | O15: =SUM(K15,M15) -> 27202 | P15: =SUM(L15,N15) -> 8330
B16: 2026 | C16: Maj | D16: =Data!L18 + 'Lån Översikt'!D55 -> 27187 | E16: 8331 | F16: 37288 | G16: 13414 | H16: =SUM(F16:G16) -> 50702 | I16: =G16/H16 -> 0.2645655 | J16: =F16/H16 -> 0.7354345 | K16: =INT(D16*I16) -> 7192 | L16: =INT(E16*I16) -> 2204 | M16: =INT(D16*J16) -> 19994 | N16: =INT(E16*J16) -> 6126 | O16: =SUM(K16,M16) -> 27186 | P16: =SUM(L16,N16) -> 8330
B17: 2026 | C17: Juni | D17: =Data!L19 + 'Lån Översikt'!D55 -> 27171 | E17: 8331 | F17: 37288 | G17: 13414 | H17: =SUM(F17:G17) -> 50702 | I17: =G17/H17 -> 0.2645655 | J17: =F17/H17 -> 0.7354345 | K17: =INT(D17*I17) -> 7188 | L17: =INT(E17*I17) -> 2204 | M17: =INT(D17*J17) -> 19982 | N17: =INT(E17*J17) -> 6126 | O17: =SUM(K17,M17) -> 27170 | P17: =SUM(L17,N17) -> 8330
B18: 2026 | C18: Juli | D18: =Data!L20 + 'Lån Översikt'!D55 -> 27155 | E18: 8331 | F18: 37288 | G18: 12804 | H18: =SUM(F18:G18) -> 50092 | I18: =G18/H18 -> 0.25560968 | J18: =F18/H18 -> 0.74439032 | K18: =INT(D18*I18) -> 6941 | L18: =INT(E18*I18) -> 2129 | M18: =INT(D18*J18) -> 20213 | N18: =INT(E18*J18) -> 6201 | O18: =SUM(K18,M18) -> 27154 | P18: =SUM(L18,N18) -> 8330
B19: 2026 | C19: Augusti | D19: =Data!L21 + 'Lån Översikt'!D55 -> 27139 | E19: 8331 | F19: 37288 | G19: 14024 | H19: =SUM(F19:G19) -> 51312 | I19: =G19/H19 -> 0.27330839 | J19: =F19/H19 -> 0.72669161 | K19: =INT(D19*I19) -> 7417 | L19: =INT(E19*I19) -> 2276 | M19: =INT(D19*J19) -> 19721 | N19: =INT(E19*J19) -> 6054 | O19: =SUM(K19,M19) -> 27138 | P19: =SUM(L19,N19) -> 8330
B20: 2026 | C20: September | D20: =Data!L22 + 'Lån Översikt'!D55 -> 27123 | E20: 8331 | F20: 37288 | G20: 12804 | H20: =SUM(F20:G20) -> 50092 | I20: =G20/H20 -> 0.25560968 | J20: =F20/H20 -> 0.74439032 | K20: =INT(D20*I20) -> 6932 | L20: =INT(E20*I20) -> 2129 | M20: =INT(D20*J20) -> 20190 | N20: =INT(E20*J20) -> 6201 | O20: =SUM(K20,M20) -> 27122 | P20: =SUM(L20,N20) -> 8330
B21: 2026 | C21: Oktober | D21: =Data!L23 + 'Lån Översikt'!D55 -> 27107 | E21: 8331 | F21: 37288 | G21: 11479 | H21: =SUM(F21:G21) -> 48767 | I21: =G21/H21 -> 0.23538458 | J21: =F21/H21 -> 0.76461542 | K21: =INT(D21*I21) -> 6380 | L21: =INT(E21*I21) -> 1960 | M21: =INT(D21*J21) -> 20726 | N21: =INT(E21*J21) -> 6370 | O21: =SUM(K21,M21) -> 27106 | P21: =SUM(L21,N21) -> 8330
B22: 2026 | C22: November | D22: =Data!L24 + 'Lån Översikt'!D55 -> 27091 | E22: 8331 | F22: 37288 | G22: 11605 | H22: =SUM(F22:G22) -> 48893 | I22: =G22/H22 -> 0.23735504 | J22: =F22/H22 -> 0.76264496 | K22: =INT(D22*I22) -> 6430 | L22: =INT(E22*I22) -> 1977 | M22: =INT(D22*J22) -> 20660 | N22: =INT(E22*J22) -> 6353 | O22: =SUM(K22,M22) -> 27090 | P22: =SUM(L22,N22) -> 8330
B23: 2026 | C23: December | D23: =Data!L25 + 'Lån Översikt'!D55 -> 27075 | E23: 8331 | F23: 37288 | G23: 10260 | H23: =SUM(F23:G23) -> 47548 | I23: =G23/H23 -> 0.21578195 | J23: =F23/H23 -> 0.78421805 | K23: =INT(D23*I23) -> 5842 | L23: =INT(E23*I23) -> 1797 | M23: =INT(D23*J23) -> 21232 | N23: =INT(E23*J23) -> 6533 | O23: =SUM(K23,M23) -> 27074 | P23: =SUM(L23,N23) -> 8330

Sheet Majas utgifter
A1: Utgifter | B1: Summa
A2: Glasögon | B2: 331
A3: Mobilabonnemang | B3: 259
A4: Kund hos Nordea | B4: 29
A5: ICA-kortet | B5: 5414
A6: Huskontot | B6: 16000
A7: Olyckfallsförsäkring | B7: 247
A8: Sparande Lysa | B8: 1000
A9: Sparande Avanza | B9: 1000
A10: Sparande Bröllop | B10: 3000
A11: Sparande Mila | B11: 500
A12: Sparande Pension | B12: 500
A14: Inkomst | B14: Summa
A15: Meltwater | B15: 25425
A16: Aktiv Ungdom | B16: 4288
A23: Förskolan | B23: 1847

Sheet Markus utgifter
A2: År | B2: Månad | C2: Inkomst | D2: Mobil | E2: Youtube | F2: Nordea | G2: CSN | H2: Huskontot | I2: Ica-kortet | J2: Försäkring | K2: Billån Maja | L2: Sparande egen | M2: Familjespar | N2: Barnspar | O2: Utgifter | P2: Kvar på kontot
A3: 2026 | B3: Januari | C3: ='Överföringar'!F12 -> 30844 | D3: 209 | E3: 199 | F3: 29 | G3: 1360 | H3: ='Överföringar'!M12 -> 13267 | I3: ='Överföringar'!N12 -> 4502 | J3: =138 -> 138 | N3: =1000 -> 1000 | O3: =SUM(D3:J3) -> 19704 | P3: =C3-O3 -> 11140
A4: 2026 | B4: Februari | C4: ='Överföringar'!F13 + 26057 -> 68977 | D4: 9 | E4: 199 | F4: 29 | G4: 1360 | H4: ='Överföringar'!M13 -> 20527 | I4: ='Överföringar'!N13 -> 6279 | J4: 138 | K4: 2775 | N4: 1000 | O4: =SUM(D4:K4) -> 31316 | P4: =C4-O4 -> 37661
